Workbook

Sheet Gebruikershandleiding
A2: Welkom!
A3: ACT = Automated Compliance Tool
A4: Deze Excel-sheet is ontwikkeld om een realistisch beeld te geven van het gebruik en de impact van geautomatiseerde compliance tools binnen een organisatie. Het doel is om, samen met Infosentry en eventueel in aanwezigheid van de klant, tot een goed onderbouwde inschatting te komen van de kosten en inspanningen op korte en lange termijn.
A5: Praktisch: vul enkel de getallen in die vet en schuingedrukt staan, zoals 105. De overige getallen worden automatisch berekend.
A6: Tabblad TCO
A7: Stap 1: Schat in hoelang je verwacht de tool te gebruiken, standaard staat dit op 3 jaar maar dit kan aangepast worden naargelang de wensen. Ook later in het proces kan dit steeds aangepast worden om een beter beeld te krijgen.
A8: Stap 2: Leg de uurlonen vast van de interne medewerker in de organisatie die compliance op zich neemt, het uurloon van de externe consultant die wordt ingehuurd als ondersteuning en tot slot het uurloon van de aangestelde auditor die de externe audit gaat uitvoeren.
A9: Stap 3: Vul hier de effectieve jaarlijkse licentiekosten in om de tool te gebruiken.
A10: (Stap 4): Hier heb je de mogelijkheid om eventueel nog andere kosten door te rekenen. Deze kosten kunnen op jaarbasis of eenmalig aangerekend worden.
A11: Tablad ROI
A12: Opgelet, er wordt een onderscheid gemaakt tussen de BUILD fase en RUN fase. De BUILD fase staat voor de periode waarin het certificeringsproces de eerste keer wordt opgestart, de volledige voorbereiding. Hiervoor rekenen we 1 jaar, het eerste jaar. Wanneer het volledige proces een eerste keer is doorlopen schakelen we over naar de RUN fase. Dit zijn alle certificeringsjaren die volgen. Het is logisch dat in het eerste jaar de werkdruk hoog is maar deze neemt af in de RUN jaren.
A13: Stap 5: Hier schat je in hoeveel tijd de BUILD fase inneemt alsook de RUN fase zonder het gebruik van een automated compliance tool. Bepaal het aantal werkuren dat nodig zijn in beide fases voor zowel de interne medewerker in de organisatie, als de externe consultant alsook de auditor.
... A20: In Conclusie komt alles samen, hier wordt weergegeven wat de TCO over een bepaalde gebruiksperiode is. Hoe snel de organisatie deze investering heeft terugveriend, het break-even point. En hoeveel ze uitsparen per jaar en over de volledige gebruiksduur. Op basis van deze cijfers kan een overwogen beslissing genomen worden.

Sheet TCO
A1: Total Cost of Ownership
A3: Stap 1: verwachte gebruiksduur van de tool, standaard 5 jaar
A4: Gebruiksduur | B4: 5 | C4: Jaren | I4: Stap 7: Korting op licentiekosten
E5: OVERZICHT | G5: Bedrag | I5: KORTING op licentiekosten | J5: 0.3 | L5: =J5 -> 0.3
A6: Stap 2: uurlonen vastleggen | E6: TCO | G6: =E15+E36+E37+E23+E31 -> 345840 | I6: Korting per jaar | J6: =C15*L5 -> 5400 | L6: =C15-J6 -> 12600
A7: Vaste uurlonen | C7: Bedrag | E7: Bedrag in eerste jaar | G7: =C15+C36+C37+C23+C31 -> 90800 | I7: ="Korting over " & B4 & " jaar" -> Korting over 5 jaar | J7: =E15*L5 -> 27000 | L7: =E15-J7 -> 63000
A8: Interne werknemer | C8: 60 | E8: Jaarlijks volgende kosten | G8: =C15+C37+D23+D31 -> 63760
A9: Externe consultant | C9: 100 | I9: TCO NA KORTING | L9: =G6-J7 -> 318840
A10: Auditor | C10: 188 | I10: Bedrag eerste jaar | L10: =L6+C36+C37+C23+C31 -> 85400
I11: Jaarlijks kosten volgende jaren | L11: =L6+C37+D23+D31 -> 58360
A13: Stap 3: licentiekosten invullen
A14: Relevante kosten | C14: Bedrag | D14: Frequentie | E14: ="Kost over " & B4 & " jaar" -> Kost over 5 jaar
A15: Licentiekosten | C15: 18000 | D15: Jaarlijks | E15: =C15*B4 -> 90000
A18: Inspanning interne werknemer | C18: BUILD - 1ste jaar | D18: RUN - volgende jaren | E18: ="Kost over " & B4 & " jaar" -> Kost over 5 jaar
A19: - Werkuren per dag | C19: 8 | D19: 8
A20: - Aantal dagen | C20: =ROI!J13+ROI!J20+ROI!J27+ROI!J35 -> 60 | D20: =ROI!K13+ROI!K20+ROI!K27+ROI!K35 -> 47
A21: - TOTAAL aantal uren | C21: =C19*C20 -> 480 | D21: =D19*D20 -> 376
A22: - Bruto uurloon | C22: =C8 -> 60 | D22: =C8 -> 60
A23: Bruto kosten interne werknemer | C23: =C22*C21 -> 28800 | D23: =D21*D22 -> 22560 | E23: =C23+(D23*(B4-1)) -> 119040
A26: Inspanning externe consultant | C26: BUILD - 1ste jaar | D26: RUN - volgende jaren | E26: ="Kost over " & B4 & " jaar" -> Kost over 5 jaar
A27: - Werkuren per dag | C27: 8 | D27: 8
A28: - Aantal dagen | C28: =ROI!L13+ROI!L20+ROI!L27+ROI!L35 -> 55 | D28: =ROI!M13+ROI!M20+ROI!M27+ROI!M35 -> 29
A29: - TOTAAL aantal uren | C29: =C27*C28 -> 440 | D29: =D27*D28 -> 232
A30: - Bruto uurloon | C30: =C9 -> 100 | D30: =C9 -> 100
A31: Bruto kosten externe consultant | C31: =C30*C29 -> 44000 | D31: =D29*D30 -> 23200 | E31: =C31+(D31*(B4-1)) -> 136800
A34: Stap 4: EVENTUELE onverwachte kosten kunnen hier ingegeven worden, zowel jaarlijkse als eenmalige.
A35: RESERVE voor onverwachte kosten | C35: Bedrag | D35: Frequentie | E35: ="Kost over " & B4 & " jaar" -> Kost over 5 jaar
A36: Andere éénmalige kosten | C36: 0 | D36: Eénmalig | E36: =C36*B4 -> 0
A37: Andere jaarlijkse kosten | C37: 0 | D37: Jaarlijks | E37: =C37*B4 -> 0

Sheet ROI
A1: Return On Investment
A3: TCO | G3: =TCO!L9 -> 318840 | I3: ACT = Automated Compliance Tool
A5: Gebruiksduur in jaren | G5: =TCO!B4 -> 5
A6: Overige jaren - RUN | G6: =TCO!B4 -1 -> 4
A8: Stap 5: Kosten en uren bepalen van jaarlijks certificeringsproces ZONDER ACT | I8: Stap 6: Kosten en uren bepalen van jaarlijks certificeringsproces MET ACT
A9: Certificeringskosten ZONDER ACT | B9: Interne werknemer | D9: Externe consultant | F9: Auditor | I9: Certificeringskosten MET ACT | J9: Interne werknemer | L9: Externe consultant | N9: Auditor
B10: BUILD | C10: RUN | D10: BUILD | E10: RUN | F10: BUILD | G10: RUN | J10: BUILD | K10: RUN | L10: BUILD | M10: RUN | N10: BUILD | O10: RUN
A11: Voorbereiding interne audit zonder ACT | I11: Voorbereiding interne audit met ACT
A12: - Werkuren per dag | B12: 8 | C12: 8 | D12: 8 | E12: 8 | I12: - Werkuren per dag | J12: 8 | K12: 8 | L12: 8 | M12: 8
A13: - Aantal dagen | B13: 60 | C13: 52 | D13: 45 | E13: 36 | I13: - Aantal dagen | J13: 50 | K13: 42 | L13: 45 | M13: 24
A14: - TOTAAL aantal uren | B14: =B12*B13 -> 480 | C14: =C12*C13 -> 416 | D14: =D12*D13 -> 360 | E14: =E12*E13 -> 288 | I14: - TOTAAL aantal uren | J14: =J12*J13 -> 400 | K14: =K12*K13 -> 336 | L14: =L12*L13 -> 360 | M14: =M12*M13 -> 192
A15: - Bruto uurloon | B15: =TCO!C8 -> 60 | C15: =TCO!C8 -> 60 | D15: =TCO!C9 -> 100 | E15: =TCO!C9 -> 100 | I15: - Bruto uurloon | J15: =TCO!C8 -> 60 | K15: =TCO!C8 -> 60 | L15: =TCO!C9 -> 100 | M15: =TCO!C9 -> 100
A16: Audit voorbereiding zonder ACT | B16: =B15*B14 -> 28800 | C16: =C15*C14 -> 24960 | D16: =D15*D14 -> 36000 | E16: =E15*E14 -> 28800 | I16: Audit voorbereiding met ACT | J16: =J15*J14 -> 24000 | K16: =K15*K14 -> 20160 | L16: =L15*L14 -> 36000 | M16: =M15*M14 -> 19200
A18: Interne audit ZONDER ACT | I18: Interne audit met ACT
A19: - Werkuren per dag | B19: 8 | C19: 8 | D19: 8 | E19: 8 | F19: 8 | G19: 8 | I19: - Werkuren per dag | J19: 8 | K19: 8 | L19: 8 | M19: 8 | N19: 8 | O19: 8
A20: - Aantal dagen | B20: 2 | C20: 2 | D20: 2 | E20: 2 | F20: 4 | G20: 4 | I20: - Aantal dagen | J20: 1 | K20: 1 | L20: 1 | M20: 1 | N20: 4 | O20: 4
A21: - TOTAAL aantal uren | B21: =B19*B20 -> 16 | C21: =C19*C20 -> 16 | D21: =D19*D20 -> 16 | E21: =E19*E20 -> 16 | F21: =F19*F20 -> 32 | G21: =G19*G20 -> 32 | I21: - TOTAAL aantal uren | J21: =J19*J20 -> 8 | K21: =K19*K20 -> 8 | L21: =L19*L20 -> 8 | M21: =M19*M20 -> 8 | N21: =N19*N20 -> 32 | O21: =O19*O20 -> 32
A22: - Bruto uurloon | B22: =TCO!C8 -> 60 | C22: =TCO!C8 -> 60 | D22: =TCO!C9 -> 100 | E22: =TCO!C9 -> 100 | F22: =TCO!C10 -> 188 | G22: =TCO!C10 -> 188 | I22: - Bruto uurloon | J22: =TCO!C8 -> 60 | K22: =TCO!C8 -> 60 | L22: =TCO!C9 -> 100 | M22: =TCO!C9 -> 100 | N22: =TCO!C10 -> 188 | O22: =TCO!C10 -> 188
A23: Bruto kosten interne audit zonder ACT | B23: =B22*B21 -> 960 | C23: =C22*C21 -> 960 | D23: =D22*D21 -> 1600 | E23: =E22*E21 -> 1600 | F23: =F22*F21 -> 6016 | G23: =G22*G21 -> 6016 | I23: Bruto kosten interne audit met ACT | J23: =J22*J21 -> 480 | K23: =K22*K21 -> 480 | L23: =L22*L21 -> 800 | M23: =M22*M21 -> 800 | N23: =N22*N21 -> 6016 | O23: =O22*O21 -> 6016
A25: Voorbereiding externe audit zonder ACT | I25: Voorbereiding externe audit met ACT
A26: - Werkuren per dag | B26: 8 | C26: 8 | D26: 8 | E26: 8 | I26: - Werkuren per dag | J26: 8 | K26: 8 | L26: 8 | M26: 8
A27: - Aantal dagen | B27: 5 | C27: 3 | D27: 5 | E27: 3 | I27: - Aantal dagen | J27: 5 | K27: 2 | L27: 5 | M27: 2
A28: - TOTAAL aantal uren | B28: =B26*B27 -> 40 | C28: =C26*C27 -> 24 | D28: =D26*D27 -> 40 | E28: =E26*E27 -> 24 | I28: - TOTAAL aantal uren | J28: =J26*J27 -> 40 | K28: =K26*K27 -> 16 | L28: =L26*L27 -> 40 | M28: =M26*M27 -> 16
A29: - Bruto uurloon | B29: =TCO!C8 -> 60 | C29: =TCO!C8 -> 60 | D29: =TCO!C9 -> 100 | E29: =TCO!C9 -> 100 | I29: - Bruto uurloon | J29: =TCO!C8 -> 60 | K29: =TCO!C8 -> 60 | L29: =TCO!C9 -> 100 | M29: =TCO!C9 -> 100
A30: Audit voorbereiding zonder ACT | B30: =B29*B28 -> 2400 | C30: =C29*C28 -> 1440 | D30: =D29*D28 -> 4000 | E30: =E29*E28 -> 2400 | I30: Audit voorbereiding met ACT | J30: =J29*J28 -> 2400 | K30: =K29*K28 -> 960 | L30: =L29*L28 -> 4000 | M30: =M29*M28 -> 1600
A33: Externe audit zonder ACT | I33: Externe audit met ACT
A34: - Werkuren per dag | B34: 8 | C34: 8 | D34: 8 | E34: 8 | F34: 8 | G34: 8 | I34: - Werkuren per dag | J34: 8 | K34: 8 | L34: 8 | M34: 8 | N34: 8 | O34: 8
A35: - Aantal dagen | B35: 4 | C35: 2 | D35: 4 | E35: 2 | F35: 6 | G35: 3 | I35: - Aantal dagen | J35: 4 | K35: 2 | L35: 4 | M35: 2 | N35: 6 | O35: 3
A36: - TOTAAL aantal uren | B36: =B34*B35 -> 32 | C36: =C34*C35 -> 16 | D36: =D34*D35 -> 32 | E36: =E34*E35 -> 16 | F36: =F34*F35 -> 48 | G36: =G34*G35 -> 24 | I36: - TOTAAL aantal uren | J36: =J34*J35 -> 32 | K36: =K34*K35 -> 16 | L36: =L34*L35 -> 32 | M36: =M34*M35 -> 16 | N36: =N34*N35 -> 48 | O36: =O34*O35 -> 24
A37: - Bruto uurloon | B37: =TCO!C8 -> 60 | C37: =TCO!C8 -> 60 | D37: =TCO!C9 -> 100 | E37: =TCO!C9 -> 100 | F37: =TCO!C10 -> 188 | G37: =TCO!C10 -> 188 | I37: - Bruto uurloon | J37: =TCO!C8 -> 60 | K37: =TCO!C8 -> 60 | L37: =TCO!C9 -> 100 | M37: =TCO!C9 -> 100 | N37: =TCO!C10 -> 188 | O37: =TCO!C10 -> 188
A38: Bruto kosten externe audit zonder ACT | B38: =B37*B36 -> 1920 | C38: =C37*C36 -> 960 | D38: =D37*D36 -> 3200 | E38: =E37*E36 -> 1600 | F38: =F37*F36 -> 9024 | G38: =G37*G36 -> 4512 | I38: Bruto kosten externe audit met ACT | J38: =J37*J36 -> 1920 | K38: =K37*K36 -> 960 | L38: =L37*L36 -> 3200 | M38: =M37*M36 -> 1600 | N38: =N37*N36 -> 9024 | O38: =O37*O36 -> 4512
B40: Interne werknemer | D40: Externe consultant | F40: Auditor | J40: Interne werknemer | L40: Externe consulant | N40: Auditor
B41: BUILD | C41: RUN | D41: BUILD | E41: RUN | F41: BUILD | G41: RUN | J41: BUILD | K41: RUN | L41: BUILD | M41: RUN | N41: BUILD | O41: RUN
A42: TOTAAL AUDIT KOSTEN zonder ACT | B42: =B16+B23+B30+B38 -> 34080 | C42: =C16+C23+C30+C38 -> 28320 | D42: =D16+D23+D30+D38 -> 44800 | E42: =E16+E23+E30+E38 -> 34400 | F42: =F23+F38 -> 15040 | G42: =G23+G38 -> 10528 | I42: TOTAAL AUDIT KOSTEN met ACT | J42: =J16+J23+J30+J38 -> 28800 | K42: =K16+K23+K30+K38 -> 22560 | L42: =L16+L23+L30+L38 -> 44000 | M42: =M16+M23+M30+M38 -> 23200 | N42: =N23+N38 -> 15040 | O42: =O23+O38 -> 10528
A43: TOTAAL AUDIT UREN zonder ACT | B43: =B14+B21+B28+B36 -> 568 | C43: =C14+C21+C28+C36 -> 472 | D43: =D14+D21+D28+D36 -> 448 | E43: =E14+E21+E28+E36 -> 344 | F43: =F21+F36 -> 80 | G43: =G21+G36 -> 56 | I43: TOTAAL AUDIT UREN met ACT | J43: =J14+J21+J28+J36 -> 480 | K43: =K14+K21+K28+K36 -> 376 | L43: =L14+L21+L28+L36 -> 440 | M43: =M14+M21+M28+M36 -> 232 | N43: =N21+N36 -> 80 | O43: =O21+O36 -> 56
I45: Jaarlijkse licentiekost | J45: =TCO!L6 -> 12600
B47: Excl. Auditorkosten | D47: Incl. Auditorkosten | J47: Excl. Auditorkosten | L47: Incl. Auditorkosten
A48: Totaal personeelskosten BUILD | C48: =B42+D42 -> 78880 | E48: =B42+D42+F42 -> 93920 | I48: Totaal personeelskosten BUILD incl. licentiekosten | K48: =J42+L42+J45 -> 85400 | M48: =J42+L42+N42+J45 -> 100440
A49: Uren BUILD | C49: =B43+D43 -> 1016 | E49: =B43+D43+F43 -> 1096 | I49: Uren BUILD | K49: =J43+L43 -> 920 | M49: =J43+L43+N43 -> 1000
A51: Totaal personeelskosten RUN | C51: =C42+E42 -> 62720 | E51: =C42+E42+G42 -> 73248 | I51: Totaal personeelskosten RUN incl. licentiekosten | K51: =K42+M42+J45 -> 58360 | M51: =K42+M42+O42+J45 -> 68888
...

Sheet Conclusie
A1: Conclusie - aankopen van Automated Compliance Tool
A4: TCO | G4: ROI
A6: KORTING op licentiekosten | B6: =TCO!J5 -> 0.3 | D6: =B6 -> 0.3 | G6: CONCLUSIE
A7: Korting per jaar | B7: =TCO!J6 -> 5400 | D7: =TCO!L6 -> 12600 | G7: =ROI!I59 -> De investering zijn ROI is na 5 jaar: | H7: =ROI!J59 -> 1.6748466
A8: =TCO!I7 -> Korting over 5 jaar | B8: =TCO!J7 -> 27000 | D8: =TCO!L7 -> 63000 | G8: De investering is terugbetaald na | H8: =ROI!C78 -> 1 jaar en 6 maanden
A10: TCO NA KORTING | D10: =TCO!L9 -> 318840 | G10: =IF(H10>=0, "Uitbesparing per jaar", "Extra kost per jaar") -> Uitbesparing per jaar | H10: =ROI!J63 -> 2184
A11: Bedrag eerste jaar | D11: =TCO!L10 -> 85400 | G11: =IF(H11>=0, "Uitbesparing over " & TCO!B4 & " jaar", "Extra kost over " & TCO!B4 & " jaar") -> Uitbesparing over 5 jaar | H11: =ROI!J64 -> 10920
A12: Jaarlijks kosten volgende jaren | D12: =TCO!L11 -> 58360

Sheet Auditdagen
